<?xml version="1.0" ?>
 <robot name="test_inductor">
<link name="base_link">
<inertial>
<mass value="1"/>
<origin xyz="0 0 0"/>
<inertia ixx="1" ixy="0" ixz="0" iyx="0" iyy="1" iyz="0" izx="0" izy="0" izz="1" />
</inertial>
<visual>
<origin rpy="0 0 0" xyz="0 0 0" />
<geometry>
<box size="0.1 0.1 0.1" />
</geometry>
</visual>
<collision>
<origin rpy="0 0 0" xyz="0 0 0" />
<geometry>
<box size="0.1 0.1 0.1" />
</geometry>
</collision>
</link>
<joint name="coupler1_joint" type="continuous">
<origin xyz="0.070711 -0.070711 0.000000"/>
<axis xyz = "0.000000 0.000000 1.000000" />
<parent link="base_link"/>
<child link="coupler1_link"/>
</joint>
<link name="coupler1_link">
<inertial>
<mass value="0.01"/>
<origin xyz="0 0 0"/>
<inertia ixx="0.01" ixy="0" ixz="0" iyx="0" iyy="0.01" iyz="0" izx="0" izy="0" izz="0.01" />
</inertial>
<visual>
<origin rpy="0.000000 0.000000 0.000000" xyz="0 0 0" />
<geometry>
<cylinder length="0.01" radius="0.02" />
</geometry>
</visual>
<collision>
<origin rpy="0 0 0" xyz="0 0 0" />
<geometry>
<box size="0.0 0.0 0.0" />
</geometry>
</collision>
</link>
<force_element name="coupler1">
<induction_coupler lower_limit="-10" upper_limit="10" scale_factor_thrust="1.0" scale_factor_moment="0.0245">
<parent link="coupler1_link"/>
<origin xyz="0 0 0"/>
<axis xyz="0.000000 0.000000 1.000000"/>
</induction_coupler>
</force_element>
<joint name="coupler2_joint" type="continuous">
<origin xyz="-0.070711 -0.070711 0.000000"/>
<axis xyz = "0.000000 0.000000 1.000000" />
<parent link="base_link"/>
<child link="coupler2_link"/>
</joint>
<link name="coupler2_link">
<inertial>
<mass value="0.01"/>
<origin xyz="0 0 0"/>
<inertia ixx="0.01" ixy="0" ixz="0" iyx="0" iyy="0.01" iyz="0" izx="0" izy="0" izz="0.01" />
</inertial>
<visual>
<origin rpy="0.000000 0.000000 0.000000" xyz="0 0 0" />
<geometry>
<cylinder length="0.01" radius="0.02" />
</geometry>
</visual>
<collision>
<origin rpy="0 0 0" xyz="0 0 0" />
<geometry>
<box size="0.0 0.0 0.0" />
</geometry>
</collision>
</link>
<force_element name="coupler2">
<induction_coupler lower_limit="-10" upper_limit="10" scale_factor_thrust="1.0" scale_factor_moment="0.0245">
<parent link="coupler2_link"/>
<origin xyz="0 0 0"/>
<axis xyz="0.000000 0.000000 1.000000"/>
</induction_coupler>
</force_element>
</robot>