<?xml version="1.0" ?>
<!-- =================================================================================== -->
<!-- |    This document was autogenerated by xacro from curve_inspector.xacro          | -->
<!-- |    EDITING THIS FILE BY HAND IS NOT RECOMMENDED                                 | -->
<!-- =================================================================================== -->
<robot name="test_inductor" xmlns:xacro="http://www.ros.org/wiki/xacro">
  <link name="base_link">
    <inertial>
      <mass value="1"/>
      <origin xyz="0 0 0"/>
      <inertia ixx="1" ixy="0" ixz="0" iyx="0" iyy="1" iyz="0" izx="0" izy="0" izz="1"/>
    </inertial>
    <visual>
      <origin rpy="0 0 0" xyz="0 0 0"/>
      <geometry>
        <box size="0.1 0.1 0.1"/>
      </geometry>
    </visual>
    <collision>
      <origin rpy="0 0 0" xyz="0 0 0"/>
      <geometry>
        <box size="0.1 0.1 0.1"/>
      </geometry>
    </collision>
  </link>
  <joint name="coupler1_joint" type="continuous">
    <origin xyz="0 0.15 -0.1"/>
    <axis xyz="1 0 0"/>
    <limit lower="-0.01" upper="0.01"/>
    <parent link="base_link"/>
    <child link="coupler1_link"/>
  </joint>
  <joint name="coupler2_joint" type="continuous">
    <origin xyz="0 -0.15 -0.1"/>
    <axis xyz="1 0 0"/>
    <limit lower="-0.01" upper="0.01"/>
    <parent link="base_link"/>
    <child link="coupler2_link"/>
  </joint>
  <link name="coupler1_link">
    <inertial>
      <mass value="0.01"/>
      <origin xyz="0 0 0"/>
      <inertia ixx="0.01" ixy="0" ixz="0" iyx="0" iyy="0.01" iyz="0" izx="0" izy="0" izz="0.01"/>
    </inertial>
    <visual>
      <origin rpy="0 0 0" xyz="0 0 0"/>
      <geometry>
        <box size="0.05 0.05 0.05"/>
      </geometry>
    </visual>
    <collision>
      <origin rpy="0 0 0" xyz="0 0 0"/>
      <geometry>
        <box size="0.0 0.0 0.0"/>
      </geometry>
    </collision>
  </link>
  <link name="coupler2_link">
    <inertial>
      <mass value="0.01"/>
      <origin xyz="0 0 0"/>
      <inertia ixx="0.01" ixy="0" ixz="0" iyx="0" iyy="0.01" iyz="0" izx="0" izy="0" izz="0.01"/>
    </inertial>
    <visual>
      <origin rpy="0 0 0" xyz="0 0 0"/>
      <geometry>
        <box size="0.05 0.05 0.05"/>
      </geometry>
    </visual>
    <collision>
      <origin rpy="0 0 0" xyz="0 0 0"/>
      <geometry>
        <box size="0.0 0.0 0.0"/>
      </geometry>
    </collision>
  </link>
  <force_element name="coupler1">
    <induction_coupler lower_limit="-10" scale_factor_moment="0.0245" scale_factor_thrust="1.0" upper_limit="10">
      <parent link="coupler1_link"/>
      <origin xyz="0 0 0"/>
      <axis xyz="1 0 0"/>
    </induction_coupler>
  </force_element>
  <force_element name="coupler1">
    <induction_coupler lower_limit="-10" scale_factor_moment="0.0245" scale_factor_thrust="1.0" upper_limit="10">
      <parent link="coupler2_link"/>
      <origin xyz="0 0 0"/>
      <axis xyz="1 0 0"/>
    </induction_coupler>
  </force_element>
  <joint name="coupler3_joint" type="continuous">
    <origin xyz="0 0.15 0"/>
    <axis xyz="0 1 0"/>
    <limit lower="-0.01" upper="0.01"/>
    <parent link="base_link"/>
    <child link="coupler3_link"/>
  </joint>
  <link name="coupler3_link">
    <inertial>
      <mass value="0.01"/>
      <origin xyz="0 0 0"/>
      <inertia ixx="0.01" ixy="0" ixz="0" iyx="0" iyy="0.01" iyz="0" izx="0" izy="0" izz="0.01"/>
    </inertial>
    <visual>
      <origin rpy="0 0 0" xyz="0 0 0"/>
      <geometry>
        <box size="0.05 0.05 0.05"/>
      </geometry>
    </visual>
    <collision>
      <origin rpy="0 0 0" xyz="0 0 0"/>
      <geometry>
        <box size="0.0 0.0 0.0"/>
      </geometry>
    </collision>
  </link>
  <force_element name="coupler1">
    <induction_coupler lower_limit="-10" scale_factor_moment="0.0245" scale_factor_thrust="1.0" upper_limit="10">
      <parent link="coupler3_link"/>
      <origin xyz="0 0 0"/>
      <axis xyz="0 1 0"/>
    </induction_coupler>
  </force_element>
  <joint name="coupler4_joint" type="continuous">
    <origin xyz="0 -0.15 0"/>
    <axis xyz="0 1 0"/>
    <limit lower="-0.01" upper="0.01"/>
    <parent link="base_link"/>
    <child link="coupler4_link"/>
  </joint>
  <link name="coupler4_link">
    <inertial>
      <mass value="0.01"/>
      <origin xyz="0 0 0"/>
      <inertia ixx="0.01" ixy="0" ixz="0" iyx="0" iyy="0.01" iyz="0" izx="0" izy="0" izz="0.01"/>
    </inertial>
    <visual>
      <origin rpy="0 0 0" xyz="0 0 0"/>
      <geometry>
        <box size="0.05 0.05 0.05"/>
      </geometry>
    </visual>
    <collision>
      <origin rpy="0 0 0" xyz="0 0 0"/>
      <geometry>
        <box size="0.0 0.0 0.0"/>
      </geometry>
    </collision>
  </link>
  <force_element name="coupler1">
    <induction_coupler lower_limit="-10" scale_factor_moment="0.0245" scale_factor_thrust="1.0" upper_limit="10">
      <parent link="coupler4_link"/>
      <origin xyz="0 0 0"/>
      <axis xyz="0 1 0"/>
    </induction_coupler>
  </force_element>
  <joint name="coupler5_joint" type="continuous">
    <origin xyz="0.15 0 0"/>
    <axis xyz="1 0 0"/>
    <limit lower="-0.01" upper="0.01"/>
    <parent link="base_link"/>
    <child link="coupler5_link"/>
  </joint>
  <link name="coupler5_link">
    <inertial>
      <mass value="0.01"/>
      <origin xyz="0 0 0"/>
      <inertia ixx="0.01" ixy="0" ixz="0" iyx="0" iyy="0.01" iyz="0" izx="0" izy="0" izz="0.01"/>
    </inertial>
    <visual>
      <origin rpy="0 0 0" xyz="0 0 0"/>
      <geometry>
        <box size="0.05 0.05 0.05"/>
      </geometry>
    </visual>
    <collision>
      <origin rpy="0 0 0" xyz="0 0 0"/>
      <geometry>
        <box size="0.0 0.0 0.0"/>
      </geometry>
    </collision>
  </link>
  <force_element name="coupler1">
    <induction_coupler lower_limit="-10" scale_factor_moment="0.0245" scale_factor_thrust="1.0" upper_limit="10">
      <parent link="coupler5_link"/>
      <origin xyz="0 0 0"/>
      <axis xyz="0 1 0"/>
    </induction_coupler>
  </force_element>
  <joint name="coupler6_joint" type="continuous">
    <origin xyz="-0.15 0 0"/>
    <axis xyz="1 0 0"/>
    <limit lower="-0.01" upper="0.01"/>
    <parent link="base_link"/>
    <child link="coupler6_link"/>
  </joint>
  <link name="coupler6_link">
    <inertial>
      <mass value="0.01"/>
      <origin xyz="0 0 0"/>
      <inertia ixx="0.01" ixy="0" ixz="0" iyx="0" iyy="0.01" iyz="0" izx="0" izy="0" izz="0.01"/>
    </inertial>
    <visual>
      <origin rpy="0 0 0" xyz="0 0 0"/>
      <geometry>
        <box size="0.05 0.05 0.05"/>
      </geometry>
    </visual>
    <collision>
      <origin rpy="0 0 0" xyz="0 0 0"/>
      <geometry>
        <box size="0.0 0.0 0.0"/>
      </geometry>
    </collision>
  </link>
  <force_element name="coupler1">
    <induction_coupler lower_limit="-10" scale_factor_moment="0.0245" scale_factor_thrust="1.0" upper_limit="10">
      <parent link="coupler6_link"/>
      <origin xyz="0 0 0"/>
      <axis xyz="1 0 0"/>
    </induction_coupler>
  </force_element>
</robot>

